[2023-05-13T21:16:02.878+0000] {taskinstance.py:1090} INFO - Dependencies all met for dep_context=non-requeueable deps ti=<TaskInstance: ny_taxi_local.create_directory.print_user manual__2023-05-13T21:13:05.779069+00:00 [queued]>
[2023-05-13T21:16:02.884+0000] {taskinstance.py:1090} INFO - Dependencies all met for dep_context=requeueable deps ti=<TaskInstance: ny_taxi_local.create_directory.print_user manual__2023-05-13T21:13:05.779069+00:00 [queued]>
[2023-05-13T21:16:02.884+0000] {taskinstance.py:1288} INFO - 
--------------------------------------------------------------------------------
[2023-05-13T21:16:02.885+0000] {taskinstance.py:1289} INFO - Starting attempt 2 of 2
[2023-05-13T21:16:02.885+0000] {taskinstance.py:1290} INFO - 
--------------------------------------------------------------------------------
[2023-05-13T21:16:02.894+0000] {taskinstance.py:1309} INFO - Executing <Task(_PythonDecoratedOperator): create_directory.print_user> on 2023-05-13 21:13:05.779069+00:00
[2023-05-13T21:16:02.898+0000] {standard_task_runner.py:55} INFO - Started process 829 to run task
[2023-05-13T21:16:02.901+0000] {standard_task_runner.py:82} INFO - Running: ['***', 'tasks', 'run', 'ny_taxi_local', 'create_directory.print_user', 'manual__2023-05-13T21:13:05.779069+00:00', '--job-id', '24', '--raw', '--subdir', 'DAGS_FOLDER/fetch_and_upload.py', '--cfg-path', '/tmp/tmpsmdtty33']
[2023-05-13T21:16:02.904+0000] {standard_task_runner.py:83} INFO - Job 24: Subtask create_directory.print_user
[2023-05-13T21:16:02.957+0000] {task_command.py:389} INFO - Running <TaskInstance: ny_taxi_local.create_directory.print_user manual__2023-05-13T21:13:05.779069+00:00 [running]> on host fdfc81637e26
[2023-05-13T21:16:03.012+0000] {taskinstance.py:1518} INFO - Exporting the following env vars:
AIRFLOW_CTX_DAG_OWNER=***
AIRFLOW_CTX_DAG_ID=ny_taxi_local
AIRFLOW_CTX_TASK_ID=create_directory.print_user
AIRFLOW_CTX_EXECUTION_DATE=2023-05-13T21:13:05.779069+00:00
AIRFLOW_CTX_TRY_NUMBER=2
AIRFLOW_CTX_DAG_RUN_ID=manual__2023-05-13T21:13:05.779069+00:00
[2023-05-13T21:16:03.014+0000] {taskinstance.py:1776} ERROR - Task failed with exception
Traceback (most recent call last):
  File "/home/airflow/.local/lib/python3.7/site-packages/airflow/decorators/base.py", line 217, in execute
    return_value = super().execute(context)
  File "/home/airflow/.local/lib/python3.7/site-packages/airflow/operators/python.py", line 175, in execute
    return_value = self.execute_callable()
  File "/home/airflow/.local/lib/python3.7/site-packages/airflow/operators/python.py", line 192, in execute_callable
    return self.python_callable(*self.op_args, **self.op_kwargs)
  File "/opt/airflow/dags/fetch_and_upload.py", line 34, in print_user
    print(os.getlogin())
OSError: [Errno 6] No such device or address
[2023-05-13T21:16:03.025+0000] {taskinstance.py:1332} INFO - Marking task as FAILED. dag_id=ny_taxi_local, task_id=create_directory.print_user, execution_date=20230513T211305, start_date=20230513T211602, end_date=20230513T211603
[2023-05-13T21:16:03.033+0000] {standard_task_runner.py:105} ERROR - Failed to execute job 24 for task create_directory.print_user ([Errno 6] No such device or address; 829)
[2023-05-13T21:16:03.075+0000] {local_task_job.py:212} INFO - Task exited with return code 1
[2023-05-13T21:16:03.092+0000] {taskinstance.py:2596} INFO - 0 downstream tasks scheduled from follow-on schedule check
