[2023-06-21T05:51:34.709+0000] {taskinstance.py:1090} INFO - Dependencies all met for dep_context=non-requeueable deps ti=<TaskInstance: showpulse_dbt_dag.dbt_run scheduled__2023-06-21T05:50:30.730012+00:00 [queued]>
[2023-06-21T05:51:34.716+0000] {taskinstance.py:1090} INFO - Dependencies all met for dep_context=requeueable deps ti=<TaskInstance: showpulse_dbt_dag.dbt_run scheduled__2023-06-21T05:50:30.730012+00:00 [queued]>
[2023-06-21T05:51:34.717+0000] {taskinstance.py:1288} INFO - 
--------------------------------------------------------------------------------
[2023-06-21T05:51:34.717+0000] {taskinstance.py:1289} INFO - Starting attempt 1 of 1
[2023-06-21T05:51:34.718+0000] {taskinstance.py:1290} INFO - 
--------------------------------------------------------------------------------
[2023-06-21T05:51:34.726+0000] {taskinstance.py:1309} INFO - Executing <Task(BashOperator): dbt_run> on 2023-06-21 05:50:30.730012+00:00
[2023-06-21T05:51:34.729+0000] {standard_task_runner.py:55} INFO - Started process 3033 to run task
[2023-06-21T05:51:34.732+0000] {standard_task_runner.py:82} INFO - Running: ['***', 'tasks', 'run', 'showpulse_dbt_dag', 'dbt_run', 'scheduled__2023-06-21T05:50:30.730012+00:00', '--job-id', '658', '--raw', '--subdir', 'DAGS_FOLDER/dbt_run.py', '--cfg-path', '/tmp/tmpm3juywcm']
[2023-06-21T05:51:34.733+0000] {standard_task_runner.py:83} INFO - Job 658: Subtask dbt_run
[2023-06-21T05:51:34.787+0000] {task_command.py:389} INFO - Running <TaskInstance: showpulse_dbt_dag.dbt_run scheduled__2023-06-21T05:50:30.730012+00:00 [running]> on host 62cfed75eae1
[2023-06-21T05:51:34.837+0000] {taskinstance.py:1518} INFO - Exporting the following env vars:
AIRFLOW_CTX_DAG_OWNER=nburkett
AIRFLOW_CTX_DAG_ID=showpulse_dbt_dag
AIRFLOW_CTX_TASK_ID=dbt_run
AIRFLOW_CTX_EXECUTION_DATE=2023-06-21T05:50:30.730012+00:00
AIRFLOW_CTX_TRY_NUMBER=1
AIRFLOW_CTX_DAG_RUN_ID=scheduled__2023-06-21T05:50:30.730012+00:00
[2023-06-21T05:51:34.838+0000] {subprocess.py:63} INFO - Tmp dir root location: 
 /tmp
[2023-06-21T05:51:34.839+0000] {subprocess.py:75} INFO - Running command: ['/bin/bash', '-c', 'cd /dbt/ticketmaster_transformation && dbt run']
[2023-06-21T05:51:34.848+0000] {subprocess.py:86} INFO - Output:
[2023-06-21T05:51:36.101+0000] {subprocess.py:93} INFO - [0m05:51:36  Running with dbt=1.5.1
[2023-06-21T05:51:36.594+0000] {subprocess.py:93} INFO - [0m05:51:36  Found 4 models, 0 tests, 0 snapshots, 0 analyses, 356 macros, 0 operations, 0 seed files, 3 sources, 0 exposures, 0 metrics, 0 groups
[2023-06-21T05:51:36.597+0000] {subprocess.py:93} INFO - [0m05:51:36
[2023-06-21T05:51:37.276+0000] {subprocess.py:93} INFO - [0m05:51:37  Concurrency: 4 threads (target='dev')
[2023-06-21T05:51:37.278+0000] {subprocess.py:93} INFO - [0m05:51:37
[2023-06-21T05:51:37.286+0000] {subprocess.py:93} INFO - [0m05:51:37  1 of 4 START sql table model twitter_kafka_pyspark_test.distinct_data .......... [RUN]
[2023-06-21T05:51:37.288+0000] {subprocess.py:93} INFO - [0m05:51:37  2 of 4 START sql table model twitter_kafka_pyspark_test.dm_events .............. [RUN]
[2023-06-21T05:51:37.290+0000] {subprocess.py:93} INFO - [0m05:51:37  3 of 4 START sql table model twitter_kafka_pyspark_test.my_first_dbt_model ..... [RUN]
[2023-06-21T05:51:41.660+0000] {subprocess.py:93} INFO - [0m05:51:41  2 of 4 OK created sql table model twitter_kafka_pyspark_test.dm_events ......... [[32mCREATE TABLE (1.3k rows, 178.2 KiB processed)[0m in 4.36s]
[2023-06-21T06:40:37.240+0000] {subprocess.py:93} INFO - [0m06:40:37  [31mUnhandled error while executing [0m
[2023-06-21T06:40:37.243+0000] {subprocess.py:93} INFO - Deadline of 600.0s exceeded while calling target function, last exception: ('Connection aborted.', RemoteDisconnected('Remote end closed connection without response'))
[2023-06-21T06:40:37.244+0000] {subprocess.py:93} INFO - [0m06:40:37  [31mUnhandled error while executing [0m
[2023-06-21T06:40:37.244+0000] {subprocess.py:93} INFO - Deadline of 600.0s exceeded while calling target function, last exception: ('Connection aborted.', RemoteDisconnected('Remote end closed connection without response'))
[2023-06-21T06:40:37.265+0000] {subprocess.py:93} INFO - [0m06:40:37  1 of 4 ERROR creating sql table model twitter_kafka_pyspark_test.distinct_data . [[31mERROR[0m in 2939.97s]
[2023-06-21T06:40:37.267+0000] {subprocess.py:93} INFO - [0m06:40:37  3 of 4 ERROR creating sql table model twitter_kafka_pyspark_test.my_first_dbt_model  [[31mERROR[0m in 2939.97s]
[2023-06-21T06:40:37.277+0000] {subprocess.py:93} INFO - [0m06:40:37  4 of 4 SKIP relation twitter_kafka_pyspark_test.my_second_dbt_model ............ [[33mSKIP[0m]
[2023-06-21T06:40:37.393+0000] {subprocess.py:93} INFO - [0m06:40:37
[2023-06-21T06:40:37.396+0000] {subprocess.py:93} INFO - [0m06:40:37  Finished running 3 table models, 1 view model in 0 hours 49 minutes and 0.79 seconds (2940.79s).
[2023-06-21T06:40:37.426+0000] {subprocess.py:93} INFO - [0m06:40:37
[2023-06-21T06:40:37.427+0000] {subprocess.py:93} INFO - [0m06:40:37  [31mCompleted with 2 errors and 0 warnings:[0m
[2023-06-21T06:40:37.428+0000] {subprocess.py:93} INFO - [0m06:40:37
[2023-06-21T06:40:37.430+0000] {subprocess.py:93} INFO - [0m06:40:37  [33mDeadline of 600.0s exceeded while calling target function, last exception: ('Connection aborted.', RemoteDisconnected('Remote end closed connection without response'))[0m
[2023-06-21T06:40:37.431+0000] {subprocess.py:93} INFO - [0m06:40:37
[2023-06-21T06:40:37.432+0000] {subprocess.py:93} INFO - [0m06:40:37  [33mDeadline of 600.0s exceeded while calling target function, last exception: ('Connection aborted.', RemoteDisconnected('Remote end closed connection without response'))[0m
[2023-06-21T06:40:37.433+0000] {subprocess.py:93} INFO - [0m06:40:37
[2023-06-21T06:40:37.434+0000] {subprocess.py:93} INFO - [0m06:40:37  Done. PASS=1 WARN=0 ERROR=2 SKIP=1 TOTAL=4
[2023-06-21T06:40:37.992+0000] {subprocess.py:97} INFO - Command exited with return code 1
[2023-06-21T06:40:38.013+0000] {taskinstance.py:1776} ERROR - Task failed with exception
Traceback (most recent call last):
  File "/home/airflow/.local/lib/python3.7/site-packages/airflow/operators/bash.py", line 197, in execute
    f"Bash command failed. The command returned a non-zero exit code {result.exit_code}."
airflow.exceptions.AirflowException: Bash command failed. The command returned a non-zero exit code 1.
[2023-06-21T06:40:38.019+0000] {taskinstance.py:1332} INFO - Marking task as FAILED. dag_id=showpulse_dbt_dag, task_id=dbt_run, execution_date=20230621T055030, start_date=20230621T055134, end_date=20230621T064038
[2023-06-21T06:40:38.035+0000] {standard_task_runner.py:105} ERROR - Failed to execute job 658 for task dbt_run (Bash command failed. The command returned a non-zero exit code 1.; 3033)
[2023-06-21T06:40:38.075+0000] {local_task_job.py:212} INFO - Task exited with return code 1
[2023-06-21T06:40:38.095+0000] {taskinstance.py:2596} INFO - 0 downstream tasks scheduled from follow-on schedule check
