[2023-06-21T18:58:56.024+0000] {taskinstance.py:1090} INFO - Dependencies all met for dep_context=non-requeueable deps ti=<TaskInstance: showpulse_dbt_dag.dbt_run scheduled__2023-06-21T18:57:51.833641+00:00 [queued]>
[2023-06-21T18:58:56.031+0000] {taskinstance.py:1090} INFO - Dependencies all met for dep_context=requeueable deps ti=<TaskInstance: showpulse_dbt_dag.dbt_run scheduled__2023-06-21T18:57:51.833641+00:00 [queued]>
[2023-06-21T18:58:56.032+0000] {taskinstance.py:1288} INFO - 
--------------------------------------------------------------------------------
[2023-06-21T18:58:56.032+0000] {taskinstance.py:1289} INFO - Starting attempt 1 of 1
[2023-06-21T18:58:56.033+0000] {taskinstance.py:1290} INFO - 
--------------------------------------------------------------------------------
[2023-06-21T18:58:56.040+0000] {taskinstance.py:1309} INFO - Executing <Task(BashOperator): dbt_run> on 2023-06-21 18:57:51.833641+00:00
[2023-06-21T18:58:56.044+0000] {standard_task_runner.py:55} INFO - Started process 5527 to run task
[2023-06-21T18:58:56.048+0000] {standard_task_runner.py:82} INFO - Running: ['***', 'tasks', 'run', 'showpulse_dbt_dag', 'dbt_run', 'scheduled__2023-06-21T18:57:51.833641+00:00', '--job-id', '930', '--raw', '--subdir', 'DAGS_FOLDER/dbt_run.py', '--cfg-path', '/tmp/tmpx4uqb6b_']
[2023-06-21T18:58:56.048+0000] {standard_task_runner.py:83} INFO - Job 930: Subtask dbt_run
[2023-06-21T18:58:56.101+0000] {task_command.py:389} INFO - Running <TaskInstance: showpulse_dbt_dag.dbt_run scheduled__2023-06-21T18:57:51.833641+00:00 [running]> on host 62cfed75eae1
[2023-06-21T18:58:56.153+0000] {taskinstance.py:1518} INFO - Exporting the following env vars:
AIRFLOW_CTX_DAG_OWNER=nburkett
AIRFLOW_CTX_DAG_ID=showpulse_dbt_dag
AIRFLOW_CTX_TASK_ID=dbt_run
AIRFLOW_CTX_EXECUTION_DATE=2023-06-21T18:57:51.833641+00:00
AIRFLOW_CTX_TRY_NUMBER=1
AIRFLOW_CTX_DAG_RUN_ID=scheduled__2023-06-21T18:57:51.833641+00:00
[2023-06-21T18:58:56.154+0000] {subprocess.py:63} INFO - Tmp dir root location: 
 /tmp
[2023-06-21T18:58:56.155+0000] {subprocess.py:75} INFO - Running command: ['/bin/bash', '-c', 'cd /dbt/ticketmaster_transformation && dbt run']
[2023-06-21T18:58:56.163+0000] {subprocess.py:86} INFO - Output:
[2023-06-21T18:58:57.413+0000] {subprocess.py:93} INFO - [0m18:58:57  Running with dbt=1.5.1
[2023-06-21T18:58:57.919+0000] {subprocess.py:93} INFO - [0m18:58:57  Found 4 models, 0 tests, 0 snapshots, 0 analyses, 356 macros, 0 operations, 0 seed files, 3 sources, 0 exposures, 0 metrics, 0 groups
[2023-06-21T18:58:57.922+0000] {subprocess.py:93} INFO - [0m18:58:57
[2023-06-21T18:58:58.931+0000] {subprocess.py:93} INFO - [0m18:58:58  Concurrency: 4 threads (target='dev')
[2023-06-21T18:58:58.932+0000] {subprocess.py:93} INFO - [0m18:58:58
[2023-06-21T18:58:58.939+0000] {subprocess.py:93} INFO - [0m18:58:58  1 of 4 START sql table model twitter_kafka_pyspark_test.distinct_data .......... [RUN]
[2023-06-21T18:58:58.941+0000] {subprocess.py:93} INFO - [0m18:58:58  2 of 4 START sql table model twitter_kafka_pyspark_test.dm_events .............. [RUN]
[2023-06-21T18:58:58.942+0000] {subprocess.py:93} INFO - [0m18:58:58  3 of 4 START sql table model twitter_kafka_pyspark_test.my_first_dbt_model ..... [RUN]
[2023-06-21T19:11:54.373+0000] {subprocess.py:93} INFO - [0m19:11:54  3 of 4 ERROR creating sql table model twitter_kafka_pyspark_test.my_first_dbt_model  [[31mERROR[0m in 775.42s]
[2023-06-21T19:11:54.376+0000] {subprocess.py:93} INFO - [0m19:11:54  1 of 4 ERROR creating sql table model twitter_kafka_pyspark_test.distinct_data . [[31mERROR[0m in 775.43s]
[2023-06-21T19:11:54.377+0000] {subprocess.py:93} INFO - [0m19:11:54  2 of 4 ERROR creating sql table model twitter_kafka_pyspark_test.dm_events ..... [[31mERROR[0m in 775.43s]
[2023-06-21T19:11:54.386+0000] {subprocess.py:93} INFO - [0m19:11:54  4 of 4 SKIP relation twitter_kafka_pyspark_test.my_second_dbt_model ............ [[33mSKIP[0m]
[2023-06-21T19:11:54.482+0000] {subprocess.py:93} INFO - [0m19:11:54
[2023-06-21T19:11:54.483+0000] {subprocess.py:93} INFO - [0m19:11:54  Finished running 3 table models, 1 view model in 0 hours 12 minutes and 56.56 seconds (776.56s).
[2023-06-21T19:11:54.503+0000] {subprocess.py:93} INFO - [0m19:11:54
[2023-06-21T19:11:54.504+0000] {subprocess.py:93} INFO - [0m19:11:54  [31mCompleted with 3 errors and 0 warnings:[0m
[2023-06-21T19:11:54.505+0000] {subprocess.py:93} INFO - [0m19:11:54
[2023-06-21T19:11:54.506+0000] {subprocess.py:93} INFO - [0m19:11:54  [33mRuntime Error in model my_first_dbt_model (models/example/my_first_dbt_model.sql)[0m
[2023-06-21T19:11:54.507+0000] {subprocess.py:93} INFO - [0m19:11:54    Deadline of 600.0s exceeded while calling target function, last exception: ('Connection aborted.', RemoteDisconnected('Remote end closed connection without response'))
[2023-06-21T19:11:54.509+0000] {subprocess.py:93} INFO - [0m19:11:54
[2023-06-21T19:11:54.510+0000] {subprocess.py:93} INFO - [0m19:11:54  [33mRuntime Error in model distinct_data (models/core/distinct_data.sql)[0m
[2023-06-21T19:11:54.511+0000] {subprocess.py:93} INFO - [0m19:11:54    Deadline of 600.0s exceeded while calling target function, last exception: ('Connection aborted.', RemoteDisconnected('Remote end closed connection without response'))
[2023-06-21T19:11:54.512+0000] {subprocess.py:93} INFO - [0m19:11:54
[2023-06-21T19:11:54.513+0000] {subprocess.py:93} INFO - [0m19:11:54  [33mRuntime Error in model dm_events (models/core/dm_events.sql)[0m
[2023-06-21T19:11:54.514+0000] {subprocess.py:93} INFO - [0m19:11:54    Deadline of 600.0s exceeded while calling target function, last exception: ('Connection aborted.', RemoteDisconnected('Remote end closed connection without response'))
[2023-06-21T19:11:54.516+0000] {subprocess.py:93} INFO - [0m19:11:54
[2023-06-21T19:11:54.517+0000] {subprocess.py:93} INFO - [0m19:11:54  Done. PASS=0 WARN=0 ERROR=3 SKIP=1 TOTAL=4
[2023-06-21T19:11:55.102+0000] {subprocess.py:97} INFO - Command exited with return code 1
[2023-06-21T19:11:55.124+0000] {taskinstance.py:1776} ERROR - Task failed with exception
Traceback (most recent call last):
  File "/home/airflow/.local/lib/python3.7/site-packages/airflow/operators/bash.py", line 197, in execute
    f"Bash command failed. The command returned a non-zero exit code {result.exit_code}."
airflow.exceptions.AirflowException: Bash command failed. The command returned a non-zero exit code 1.
[2023-06-21T19:11:55.132+0000] {taskinstance.py:1332} INFO - Marking task as FAILED. dag_id=showpulse_dbt_dag, task_id=dbt_run, execution_date=20230621T185751, start_date=20230621T185856, end_date=20230621T191155
[2023-06-21T19:11:55.170+0000] {standard_task_runner.py:105} ERROR - Failed to execute job 930 for task dbt_run (Bash command failed. The command returned a non-zero exit code 1.; 5527)
[2023-06-21T19:11:55.212+0000] {local_task_job.py:212} INFO - Task exited with return code 1
[2023-06-21T19:11:55.232+0000] {taskinstance.py:2596} INFO - 0 downstream tasks scheduled from follow-on schedule check
